[rospy.client][INFO] 2017-03-30 15:46:18,346: init_node, name[/acrobot_rqt], pid[12888]
[xmlrpc][INFO] 2017-03-30 15:46:18,346: XML-RPC server binding to 0.0.0.0:0
[xmlrpc][INFO] 2017-03-30 15:46:18,347: Started XML-RPC server [http://hancheol:45240/]
[rospy.impl.masterslave][INFO] 2017-03-30 15:46:18,347: _ready: http://hancheol:45240/
[rospy.init][INFO] 2017-03-30 15:46:18,347: ROS Slave URI: [http://hancheol:45240/]
[rospy.registration][INFO] 2017-03-30 15:46:18,347: Registering with master node http://localhost:11311
[xmlrpc][INFO] 2017-03-30 15:46:18,347: xml rpc node: starting XML-RPC server
[rospy.init][INFO] 2017-03-30 15:46:18,448: registered with master
[rospy.rosout][INFO] 2017-03-30 15:46:18,448: initializing /rosout core topic
[rospy.rosout][INFO] 2017-03-30 15:46:18,450: connected to core topic /rosout
[rospy.simtime][INFO] 2017-03-30 15:46:18,452: initializing /clock core topic
[rospy.simtime][INFO] 2017-03-30 15:46:18,455: connected to core topic /clock
[rospy.internal][INFO] 2017-03-30 15:46:18,752: topic[/rosout] adding connection to [/rosout], count 0
[rospy.internal][INFO] 2017-03-30 15:46:18,757: topic[/clock] adding connection to [http://hancheol:36004/], count 0
[rospy.internal][INFO] 2017-03-30 15:46:20,434: topic[/rrbot/camera1/parameter_updates] adding connection to [http://hancheol:36004/], count 0
[rospy.internal][INFO] 2017-03-30 15:46:20,461: topic[/rrbot/camera1/image_raw/compressed/parameter_descriptions] adding connection to [http://hancheol:36004/], count 0
[rospy.internal][INFO] 2017-03-30 15:46:20,472: topic[/rrbot/camera1/image_raw/compressed/parameter_updates] adding connection to [http://hancheol:36004/], count 0
[rospy.internal][INFO] 2017-03-30 15:46:20,478: topic[/rrbot/camera1/image_raw/theora/parameter_updates] adding connection to [http://hancheol:36004/], count 0
[rospy.internal][INFO] 2017-03-30 15:46:20,504: topic[/rrbot/camera1/image_raw/theora/parameter_descriptions] adding connection to [http://hancheol:36004/], count 0
[rospy.internal][INFO] 2017-03-30 15:46:20,514: topic[/rrbot/camera1/image_raw/compressedDepth/parameter_updates] adding connection to [http://hancheol:36004/], count 0
[rospy.internal][INFO] 2017-03-30 15:46:20,517: topic[/gazebo/parameter_updates] adding connection to [http://hancheol:36004/], count 0
[rospy.internal][INFO] 2017-03-30 15:46:20,518: topic[/rrbot/camera1/image_raw/compressedDepth/parameter_descriptions] adding connection to [http://hancheol:36004/], count 0
[rospy.internal][INFO] 2017-03-30 15:46:20,524: topic[/gazebo/parameter_descriptions] adding connection to [http://hancheol:36004/], count 0
[rospy.internal][INFO] 2017-03-30 15:46:20,525: topic[/rrbot/camera1/parameter_descriptions] adding connection to [http://hancheol:36004/], count 0
[rospy.internal][INFO] 2017-03-30 15:46:23,089: topic[/rrbot/joint1_position_controller/command] adding connection to [http://hancheol:45240/], count 0
[rospy.internal][INFO] 2017-03-30 15:46:23,096: topic[/rrbot/joint1_position_controller/command] adding connection to [/acrobot_rqt], count 0
[rospy.internal][INFO] 2017-03-30 15:46:42,955: topic[/rrbot/joint_states] adding connection to [/acrobot_control_node], count 0
[rospy.internal][INFO] 2017-03-30 15:46:43,143: topic[/rrbot/joint_states] adding connection to [/robot_state_publisher], count 1
[rospy.internal][INFO] 2017-03-30 15:48:22,139: topic[/rrbot/joint_states] adding connection to [http://hancheol:36004/], count 0
[rospy.internal][INFO] 2017-03-30 15:48:22,141: topic[/rrbot/joint_states] adding connection to [http://hancheol:45240/], count 1
[rospy.internal][INFO] 2017-03-30 15:48:22,153: topic[/rrbot/joint_states] adding connection to [/acrobot_rqt], count 2
[rospy.internal][INFO] 2017-03-30 15:49:16,200: topic impl's ref count is zero, deleting topic /rrbot/joint1_position_controller/command...
[rospy.internal][WARNING] 2017-03-30 15:49:16,202: Unknown error initiating TCP/IP socket to hancheol:36534 (http://hancheol:45240/): Traceback (most recent call last):
  File "/opt/ros/kinetic/lib/python2.7/dist-packages/rospy/impl/tcpros_base.py", line 558, in connect
    self.local_endpoint = self.socket.getsockname()
AttributeError: 'NoneType' object has no attribute 'getsockname'

[rospy.internal][INFO] 2017-03-30 15:49:16,202: topic[/rrbot/joint1_position_controller/command] adding connection to [/acrobot_rqt], count 1
[rospy.internal][INFO] 2017-03-30 15:49:16,203: topic[/rrbot/joint1_position_controller/command] removing connection to /acrobot_rqt
[rospy.internal][INFO] 2017-03-30 15:49:16,201: topic[/rrbot/joint1_position_controller/command] removing connection to http://hancheol:45240/
[rospy.internal][INFO] 2017-03-30 15:49:16,440: topic[/rrbot/joint1_position_controller/command] removing connection to /acrobot_rqt
[rospy.internal][INFO] 2017-03-30 15:51:13,569: topic[/rrbot/joint_states] adding connection to [/acrobot_control_node], count 3
[rospy.internal][INFO] 2017-03-30 15:51:13,569: topic[/rrbot/joint_states] removing connection to /acrobot_control_node
[rospy.internal][INFO] 2017-03-30 15:51:14,032: topic[/rrbot/joint_states] removing connection to /robot_state_publisher
[rospy.internal][INFO] 2017-03-30 15:51:14,033: topic[/rrbot/joint_states] removing connection to /acrobot_control_node
[rospy.internal][ERROR] 2017-03-30 15:51:14,578: Unable to initiate TCP/IP socket to hancheol:38363 (http://hancheol:36004/): Traceback (most recent call last):
  File "/opt/ros/kinetic/lib/python2.7/dist-packages/rospy/impl/tcpros_base.py", line 557, in connect
    self.read_header()
  File "/opt/ros/kinetic/lib/python2.7/dist-packages/rospy/impl/tcpros_base.py", line 650, in read_header
    self._validate_header(read_ros_handshake_header(sock, self.read_buff, self.protocol.buff_size))
  File "/opt/ros/kinetic/lib/python2.7/dist-packages/rospy/impl/tcpros_base.py", line 593, in _validate_header
    raise TransportInitError("remote error reported: %s"%header['error'])
TransportInitError: remote error reported: received a connection for a nonexistent topic [/rrbot/joint_states] from [TCPROS connection on port 38363 to [127.0.0.1:46376 on socket 54]] [/acrobot_rqt].

[rospy.internal][ERROR] 2017-03-30 15:51:15,579: Unable to initiate TCP/IP socket to hancheol:38363 (http://hancheol:36004/): Traceback (most recent call last):
  File "/opt/ros/kinetic/lib/python2.7/dist-packages/rospy/impl/tcpros_base.py", line 557, in connect
    self.read_header()
  File "/opt/ros/kinetic/lib/python2.7/dist-packages/rospy/impl/tcpros_base.py", line 650, in read_header
    self._validate_header(read_ros_handshake_header(sock, self.read_buff, self.protocol.buff_size))
  File "/opt/ros/kinetic/lib/python2.7/dist-packages/rospy/impl/tcpros_base.py", line 593, in _validate_header
    raise TransportInitError("remote error reported: %s"%header['error'])
TransportInitError: remote error reported: received a connection for a nonexistent topic [/rrbot/joint_states] from [TCPROS connection on port 38363 to [127.0.0.1:46382 on socket 54]] [/acrobot_rqt].

[rospy.internal][ERROR] 2017-03-30 15:51:17,582: Unable to initiate TCP/IP socket to hancheol:38363 (http://hancheol:36004/): Traceback (most recent call last):
  File "/opt/ros/kinetic/lib/python2.7/dist-packages/rospy/impl/tcpros_base.py", line 557, in connect
    self.read_header()
  File "/opt/ros/kinetic/lib/python2.7/dist-packages/rospy/impl/tcpros_base.py", line 650, in read_header
    self._validate_header(read_ros_handshake_header(sock, self.read_buff, self.protocol.buff_size))
  File "/opt/ros/kinetic/lib/python2.7/dist-packages/rospy/impl/tcpros_base.py", line 593, in _validate_header
    raise TransportInitError("remote error reported: %s"%header['error'])
TransportInitError: remote error reported: received a connection for a nonexistent topic [/rrbot/joint_states] from [TCPROS connection on port 38363 to [127.0.0.1:46384 on socket 16]] [/acrobot_rqt].

[rospy.internal][ERROR] 2017-03-30 15:51:17,672: Unable to initiate TCP/IP socket to hancheol:38363 (http://hancheol:36004/): Traceback (most recent call last):
  File "/opt/ros/kinetic/lib/python2.7/dist-packages/rospy/impl/tcpros_base.py", line 557, in connect
    self.read_header()
  File "/opt/ros/kinetic/lib/python2.7/dist-packages/rospy/impl/tcpros_base.py", line 650, in read_header
    self._validate_header(read_ros_handshake_header(sock, self.read_buff, self.protocol.buff_size))
  File "/opt/ros/kinetic/lib/python2.7/dist-packages/rospy/impl/tcpros_base.py", line 593, in _validate_header
    raise TransportInitError("remote error reported: %s"%header['error'])
TransportInitError: remote error reported: received a connection for a nonexistent topic [/clock] from [TCPROS connection on port 38363 to [127.0.0.1:46394 on socket 17]] [/acrobot_rqt].

[rospy.internal][ERROR] 2017-03-30 15:51:17,709: Unable to initiate TCP/IP socket to hancheol:38363 (http://hancheol:36004/): Traceback (most recent call last):
  File "/opt/ros/kinetic/lib/python2.7/dist-packages/rospy/impl/tcpros_base.py", line 557, in connect
    self.read_header()
  File "/opt/ros/kinetic/lib/python2.7/dist-packages/rospy/impl/tcpros_base.py", line 650, in read_header
    self._validate_header(read_ros_handshake_header(sock, self.read_buff, self.protocol.buff_size))
  File "/opt/ros/kinetic/lib/python2.7/dist-packages/rospy/impl/tcpros_base.py", line 593, in _validate_header
    raise TransportInitError("remote error reported: %s"%header['error'])
TransportInitError: remote error reported: received a connection for a nonexistent topic [/gazebo/parameter_updates] from [TCPROS connection on port 38363 to [127.0.0.1:46454 on socket 24]] [/acrobot_rqt].

[rospy.internal][ERROR] 2017-03-30 15:51:17,709: Unable to initiate TCP/IP socket to hancheol:38363 (http://hancheol:36004/): Traceback (most recent call last):
  File "/opt/ros/kinetic/lib/python2.7/dist-packages/rospy/impl/tcpros_base.py", line 557, in connect
    self.read_header()
  File "/opt/ros/kinetic/lib/python2.7/dist-packages/rospy/impl/tcpros_base.py", line 650, in read_header
    self._validate_header(read_ros_handshake_header(sock, self.read_buff, self.protocol.buff_size))
  File "/opt/ros/kinetic/lib/python2.7/dist-packages/rospy/impl/tcpros_base.py", line 593, in _validate_header
    raise TransportInitError("remote error reported: %s"%header['error'])
TransportInitError: remote error reported: received a connection for a nonexistent topic [/gazebo/parameter_descriptions] from [TCPROS connection on port 38363 to [127.0.0.1:46450 on socket 17]] [/acrobot_rqt].

[rospy.internal][ERROR] 2017-03-30 15:51:18,673: Unable to initiate TCP/IP socket to hancheol:38363 (http://hancheol:36004/): Traceback (most recent call last):
  File "/opt/ros/kinetic/lib/python2.7/dist-packages/rospy/impl/tcpros_base.py", line 557, in connect
    self.read_header()
  File "/opt/ros/kinetic/lib/python2.7/dist-packages/rospy/impl/tcpros_base.py", line 650, in read_header
    self._validate_header(read_ros_handshake_header(sock, self.read_buff, self.protocol.buff_size))
  File "/opt/ros/kinetic/lib/python2.7/dist-packages/rospy/impl/tcpros_base.py", line 593, in _validate_header
    raise TransportInitError("remote error reported: %s"%header['error'])
TransportInitError: remote error reported: received a connection for a nonexistent topic [/clock] from [TCPROS connection on port 38363 to [127.0.0.1:46462 on socket 15]] [/acrobot_rqt].

[rospy.internal][ERROR] 2017-03-30 15:51:18,712: Unable to initiate TCP/IP socket to hancheol:38363 (http://hancheol:36004/): Traceback (most recent call last):
  File "/opt/ros/kinetic/lib/python2.7/dist-packages/rospy/impl/tcpros_base.py", line 557, in connect
    self.read_header()
  File "/opt/ros/kinetic/lib/python2.7/dist-packages/rospy/impl/tcpros_base.py", line 650, in read_header
    self._validate_header(read_ros_handshake_header(sock, self.read_buff, self.protocol.buff_size))
  File "/opt/ros/kinetic/lib/python2.7/dist-packages/rospy/impl/tcpros_base.py", line 593, in _validate_header
    raise TransportInitError("remote error reported: %s"%header['error'])
TransportInitError: remote error reported: received a connection for a nonexistent topic [/gazebo/parameter_descriptions] from [TCPROS connection on port 38363 to [127.0.0.1:46464 on socket 17]] [/acrobot_rqt].

[rospy.internal][ERROR] 2017-03-30 15:51:18,712: Unable to initiate TCP/IP socket to hancheol:38363 (http://hancheol:36004/): Traceback (most recent call last):
  File "/opt/ros/kinetic/lib/python2.7/dist-packages/rospy/impl/tcpros_base.py", line 557, in connect
    self.read_header()
  File "/opt/ros/kinetic/lib/python2.7/dist-packages/rospy/impl/tcpros_base.py", line 650, in read_header
    self._validate_header(read_ros_handshake_header(sock, self.read_buff, self.protocol.buff_size))
  File "/opt/ros/kinetic/lib/python2.7/dist-packages/rospy/impl/tcpros_base.py", line 593, in _validate_header
    raise TransportInitError("remote error reported: %s"%header['error'])
TransportInitError: remote error reported: received a connection for a nonexistent topic [/gazebo/parameter_updates] from [TCPROS connection on port 38363 to [127.0.0.1:46466 on socket 15]] [/acrobot_rqt].

[rospy.internal][ERROR] 2017-03-30 15:51:20,676: Unable to initiate TCP/IP socket to hancheol:38363 (http://hancheol:36004/): Traceback (most recent call last):
  File "/opt/ros/kinetic/lib/python2.7/dist-packages/rospy/impl/tcpros_base.py", line 557, in connect
    self.read_header()
  File "/opt/ros/kinetic/lib/python2.7/dist-packages/rospy/impl/tcpros_base.py", line 650, in read_header
    self._validate_header(read_ros_handshake_header(sock, self.read_buff, self.protocol.buff_size))
  File "/opt/ros/kinetic/lib/python2.7/dist-packages/rospy/impl/tcpros_base.py", line 593, in _validate_header
    raise TransportInitError("remote error reported: %s"%header['error'])
TransportInitError: remote error reported: received a connection for a nonexistent topic [/clock] from [TCPROS connection on port 38363 to [127.0.0.1:46468 on socket 15]] [/acrobot_rqt].

[rospy.internal][ERROR] 2017-03-30 15:51:20,714: Unable to initiate TCP/IP socket to hancheol:38363 (http://hancheol:36004/): Traceback (most recent call last):
  File "/opt/ros/kinetic/lib/python2.7/dist-packages/rospy/impl/tcpros_base.py", line 557, in connect
    self.read_header()
  File "/opt/ros/kinetic/lib/python2.7/dist-packages/rospy/impl/tcpros_base.py", line 650, in read_header
    self._validate_header(read_ros_handshake_header(sock, self.read_buff, self.protocol.buff_size))
  File "/opt/ros/kinetic/lib/python2.7/dist-packages/rospy/impl/tcpros_base.py", line 593, in _validate_header
    raise TransportInitError("remote error reported: %s"%header['error'])
TransportInitError: remote error reported: received a connection for a nonexistent topic [/gazebo/parameter_descriptions] from [TCPROS connection on port 38363 to [127.0.0.1:46470 on socket 15]] [/acrobot_rqt].

[rospy.internal][ERROR] 2017-03-30 15:51:20,716: Unable to initiate TCP/IP socket to hancheol:38363 (http://hancheol:36004/): Traceback (most recent call last):
  File "/opt/ros/kinetic/lib/python2.7/dist-packages/rospy/impl/tcpros_base.py", line 557, in connect
    self.read_header()
  File "/opt/ros/kinetic/lib/python2.7/dist-packages/rospy/impl/tcpros_base.py", line 650, in read_header
    self._validate_header(read_ros_handshake_header(sock, self.read_buff, self.protocol.buff_size))
  File "/opt/ros/kinetic/lib/python2.7/dist-packages/rospy/impl/tcpros_base.py", line 593, in _validate_header
    raise TransportInitError("remote error reported: %s"%header['error'])
TransportInitError: remote error reported: received a connection for a nonexistent topic [/gazebo/parameter_updates] from [TCPROS connection on port 38363 to [127.0.0.1:46472 on socket 15]] [/acrobot_rqt].

[rospy.internal][ERROR] 2017-03-30 15:51:21,588: Unable to initiate TCP/IP socket to hancheol:38363 (http://hancheol:36004/): Traceback (most recent call last):
  File "/opt/ros/kinetic/lib/python2.7/dist-packages/rospy/impl/tcpros_base.py", line 557, in connect
    self.read_header()
  File "/opt/ros/kinetic/lib/python2.7/dist-packages/rospy/impl/tcpros_base.py", line 650, in read_header
    self._validate_header(read_ros_handshake_header(sock, self.read_buff, self.protocol.buff_size))
  File "/opt/ros/kinetic/lib/python2.7/dist-packages/rospy/impl/tcpros_base.py", line 593, in _validate_header
    raise TransportInitError("remote error reported: %s"%header['error'])
TransportInitError: remote error reported: received a connection for a nonexistent topic [/rrbot/joint_states] from [TCPROS connection on port 38363 to [127.0.0.1:46474 on socket 15]] [/acrobot_rqt].

[rospy.internal][ERROR] 2017-03-30 15:51:24,683: Unable to initiate TCP/IP socket to hancheol:38363 (http://hancheol:36004/): Traceback (most recent call last):
  File "/opt/ros/kinetic/lib/python2.7/dist-packages/rospy/impl/tcpros_base.py", line 557, in connect
    self.read_header()
  File "/opt/ros/kinetic/lib/python2.7/dist-packages/rospy/impl/tcpros_base.py", line 650, in read_header
    self._validate_header(read_ros_handshake_header(sock, self.read_buff, self.protocol.buff_size))
  File "/opt/ros/kinetic/lib/python2.7/dist-packages/rospy/impl/tcpros_base.py", line 593, in _validate_header
    raise TransportInitError("remote error reported: %s"%header['error'])
TransportInitError: remote error reported: received a connection for a nonexistent topic [/clock] from [TCPROS connection on port 38363 to [127.0.0.1:46476 on socket 15]] [/acrobot_rqt].

[rospy.internal][ERROR] 2017-03-30 15:51:24,718: Unable to initiate TCP/IP socket to hancheol:38363 (http://hancheol:36004/): Traceback (most recent call last):
  File "/opt/ros/kinetic/lib/python2.7/dist-packages/rospy/impl/tcpros_base.py", line 557, in connect
    self.read_header()
  File "/opt/ros/kinetic/lib/python2.7/dist-packages/rospy/impl/tcpros_base.py", line 650, in read_header
    self._validate_header(read_ros_handshake_header(sock, self.read_buff, self.protocol.buff_size))
  File "/opt/ros/kinetic/lib/python2.7/dist-packages/rospy/impl/tcpros_base.py", line 593, in _validate_header
    raise TransportInitError("remote error reported: %s"%header['error'])
TransportInitError: remote error reported: received a connection for a nonexistent topic [/gazebo/parameter_descriptions] from [TCPROS connection on port 38363 to [127.0.0.1:46478 on socket 15]] [/acrobot_rqt].

[rospy.internal][ERROR] 2017-03-30 15:51:24,721: Unable to initiate TCP/IP socket to hancheol:38363 (http://hancheol:36004/): Traceback (most recent call last):
  File "/opt/ros/kinetic/lib/python2.7/dist-packages/rospy/impl/tcpros_base.py", line 557, in connect
    self.read_header()
  File "/opt/ros/kinetic/lib/python2.7/dist-packages/rospy/impl/tcpros_base.py", line 650, in read_header
    self._validate_header(read_ros_handshake_header(sock, self.read_buff, self.protocol.buff_size))
  File "/opt/ros/kinetic/lib/python2.7/dist-packages/rospy/impl/tcpros_base.py", line 593, in _validate_header
    raise TransportInitError("remote error reported: %s"%header['error'])
TransportInitError: remote error reported: received a connection for a nonexistent topic [/gazebo/parameter_updates] from [TCPROS connection on port 38363 to [127.0.0.1:46480 on socket 15]] [/acrobot_rqt].

[rospy.internal][ERROR] 2017-03-30 15:51:29,596: Unable to initiate TCP/IP socket to hancheol:38363 (http://hancheol:36004/): Traceback (most recent call last):
  File "/opt/ros/kinetic/lib/python2.7/dist-packages/rospy/impl/tcpros_base.py", line 557, in connect
    self.read_header()
  File "/opt/ros/kinetic/lib/python2.7/dist-packages/rospy/impl/tcpros_base.py", line 650, in read_header
    self._validate_header(read_ros_handshake_header(sock, self.read_buff, self.protocol.buff_size))
  File "/opt/ros/kinetic/lib/python2.7/dist-packages/rospy/impl/tcpros_base.py", line 593, in _validate_header
    raise TransportInitError("remote error reported: %s"%header['error'])
TransportInitError: remote error reported: received a connection for a nonexistent topic [/rrbot/joint_states] from [TCPROS connection on port 38363 to [127.0.0.1:46482 on socket 15]] [/acrobot_rqt].

[rospy.internal][ERROR] 2017-03-30 15:51:30,899: Unable to initiate TCP/IP socket to hancheol:38363 (http://hancheol:36004/): Traceback (most recent call last):
  File "/opt/ros/kinetic/lib/python2.7/dist-packages/rospy/impl/tcpros_base.py", line 557, in connect
    self.read_header()
  File "/opt/ros/kinetic/lib/python2.7/dist-packages/rospy/impl/tcpros_base.py", line 650, in read_header
    self._validate_header(read_ros_handshake_header(sock, self.read_buff, self.protocol.buff_size))
  File "/opt/ros/kinetic/lib/python2.7/dist-packages/rospy/impl/tcpros_base.py", line 593, in _validate_header
    raise TransportInitError("remote error reported: %s"%header['error'])
TransportInitError: remote error reported: received a connection for a nonexistent topic [/rrbot/camera1/image_raw/compressedDepth/parameter_descriptions] from [TCPROS connection on port 38363 to [127.0.0.1:46512 on socket 16]] [/acrobot_rqt].

[rospy.internal][ERROR] 2017-03-30 15:51:30,900: Unable to initiate TCP/IP socket to hancheol:38363 (http://hancheol:36004/): Traceback (most recent call last):
  File "/opt/ros/kinetic/lib/python2.7/dist-packages/rospy/impl/tcpros_base.py", line 557, in connect
    self.read_header()
  File "/opt/ros/kinetic/lib/python2.7/dist-packages/rospy/impl/tcpros_base.py", line 650, in read_header
    self._validate_header(read_ros_handshake_header(sock, self.read_buff, self.protocol.buff_size))
  File "/opt/ros/kinetic/lib/python2.7/dist-packages/rospy/impl/tcpros_base.py", line 593, in _validate_header
    raise TransportInitError("remote error reported: %s"%header['error'])
TransportInitError: remote error reported: received a connection for a nonexistent topic [/rrbot/camera1/image_raw/compressedDepth/parameter_updates] from [TCPROS connection on port 38363 to [127.0.0.1:46516 on socket 16]] [/acrobot_rqt].

[rospy.internal][ERROR] 2017-03-30 15:51:30,904: Unable to initiate TCP/IP socket to hancheol:38363 (http://hancheol:36004/): Traceback (most recent call last):
  File "/opt/ros/kinetic/lib/python2.7/dist-packages/rospy/impl/tcpros_base.py", line 557, in connect
    self.read_header()
  File "/opt/ros/kinetic/lib/python2.7/dist-packages/rospy/impl/tcpros_base.py", line 650, in read_header
    self._validate_header(read_ros_handshake_header(sock, self.read_buff, self.protocol.buff_size))
  File "/opt/ros/kinetic/lib/python2.7/dist-packages/rospy/impl/tcpros_base.py", line 593, in _validate_header
    raise TransportInitError("remote error reported: %s"%header['error'])
TransportInitError: remote error reported: received a connection for a nonexistent topic [/rrbot/camera1/image_raw/compressed/parameter_descriptions] from [TCPROS connection on port 38363 to [127.0.0.1:46522 on socket 16]] [/acrobot_rqt].

[rospy.internal][ERROR] 2017-03-30 15:51:30,905: Unable to initiate TCP/IP socket to hancheol:38363 (http://hancheol:36004/): Traceback (most recent call last):
  File "/opt/ros/kinetic/lib/python2.7/dist-packages/rospy/impl/tcpros_base.py", line 557, in connect
    self.read_header()
  File "/opt/ros/kinetic/lib/python2.7/dist-packages/rospy/impl/tcpros_base.py", line 650, in read_header
    self._validate_header(read_ros_handshake_header(sock, self.read_buff, self.protocol.buff_size))
  File "/opt/ros/kinetic/lib/python2.7/dist-packages/rospy/impl/tcpros_base.py", line 593, in _validate_header
    raise TransportInitError("remote error reported: %s"%header['error'])
TransportInitError: remote error reported: received a connection for a nonexistent topic [/rrbot/camera1/image_raw/compressed/parameter_updates] from [TCPROS connection on port 38363 to [127.0.0.1:46526 on socket 16]] [/acrobot_rqt].

[rospy.internal][ERROR] 2017-03-30 15:51:30,908: Unable to initiate TCP/IP socket to hancheol:38363 (http://hancheol:36004/): Traceback (most recent call last):
  File "/opt/ros/kinetic/lib/python2.7/dist-packages/rospy/impl/tcpros_base.py", line 557, in connect
    self.read_header()
  File "/opt/ros/kinetic/lib/python2.7/dist-packages/rospy/impl/tcpros_base.py", line 650, in read_header
    self._validate_header(read_ros_handshake_header(sock, self.read_buff, self.protocol.buff_size))
  File "/opt/ros/kinetic/lib/python2.7/dist-packages/rospy/impl/tcpros_base.py", line 593, in _validate_header
    raise TransportInitError("remote error reported: %s"%header['error'])
TransportInitError: remote error reported: received a connection for a nonexistent topic [/rrbot/camera1/image_raw/theora/parameter_descriptions] from [TCPROS connection on port 38363 to [127.0.0.1:46530 on socket 16]] [/acrobot_rqt].

[rospy.internal][ERROR] 2017-03-30 15:51:30,908: Unable to initiate TCP/IP socket to hancheol:38363 (http://hancheol:36004/): Traceback (most recent call last):
  File "/opt/ros/kinetic/lib/python2.7/dist-packages/rospy/impl/tcpros_base.py", line 557, in connect
    self.read_header()
  File "/opt/ros/kinetic/lib/python2.7/dist-packages/rospy/impl/tcpros_base.py", line 650, in read_header
    self._validate_header(read_ros_handshake_header(sock, self.read_buff, self.protocol.buff_size))
  File "/opt/ros/kinetic/lib/python2.7/dist-packages/rospy/impl/tcpros_base.py", line 593, in _validate_header
    raise TransportInitError("remote error reported: %s"%header['error'])
TransportInitError: remote error reported: received a connection for a nonexistent topic [/rrbot/camera1/image_raw/theora/parameter_updates] from [TCPROS connection on port 38363 to [127.0.0.1:46536 on socket 16]] [/acrobot_rqt].

[rospy.internal][WARNING] 2017-03-30 15:51:31,114: Unknown error initiating TCP/IP socket to hancheol:38363 (http://hancheol:36004/): Traceback (most recent call last):
  File "/opt/ros/kinetic/lib/python2.7/dist-packages/rospy/impl/tcpros_base.py", line 557, in connect
    self.read_header()
  File "/opt/ros/kinetic/lib/python2.7/dist-packages/rospy/impl/tcpros_base.py", line 650, in read_header
    self._validate_header(read_ros_handshake_header(sock, self.read_buff, self.protocol.buff_size))
  File "/opt/ros/kinetic/lib/python2.7/dist-packages/rosgraph/network.py", line 362, in read_ros_handshake_header
    d = sock.recv(buff_size)
error: [Errno 104] Connection reset by peer

[rospy.internal][INFO] 2017-03-30 15:51:31,115: topic[/rrbot/camera1/parameter_descriptions] removing connection to http://hancheol:36004/
[rospy.internal][WARNING] 2017-03-30 15:51:31,115: Unknown error initiating TCP/IP socket to hancheol:38363 (http://hancheol:36004/): Traceback (most recent call last):
  File "/opt/ros/kinetic/lib/python2.7/dist-packages/rospy/impl/tcpros_base.py", line 557, in connect
    self.read_header()
  File "/opt/ros/kinetic/lib/python2.7/dist-packages/rospy/impl/tcpros_base.py", line 650, in read_header
    self._validate_header(read_ros_handshake_header(sock, self.read_buff, self.protocol.buff_size))
  File "/opt/ros/kinetic/lib/python2.7/dist-packages/rosgraph/network.py", line 362, in read_ros_handshake_header
    d = sock.recv(buff_size)
error: [Errno 104] Connection reset by peer

[rospy.internal][INFO] 2017-03-30 15:51:31,115: topic[/rrbot/camera1/parameter_updates] removing connection to http://hancheol:36004/
[rospy.internal][INFO] 2017-03-30 15:51:31,675: topic[/rosout] removing connection to /rosout
[rospy.internal][WARNING] 2017-03-30 15:51:31,902: Unknown error initiating TCP/IP socket to hancheol:38363 (http://hancheol:36004/): Traceback (most recent call last):
  File "/opt/ros/kinetic/lib/python2.7/dist-packages/rospy/impl/tcpros_base.py", line 555, in connect
    self.socket.connect((dest_addr, dest_port))
  File "/usr/lib/python2.7/socket.py", line 228, in meth
    return getattr(self._sock,name)(*args)
error: [Errno 111] Connection refused

[rospy.internal][INFO] 2017-03-30 15:51:31,904: topic[/rrbot/camera1/image_raw/compressedDepth/parameter_descriptions] removing connection to http://hancheol:36004/
[rospy.internal][WARNING] 2017-03-30 15:51:31,908: Unknown error initiating TCP/IP socket to hancheol:38363 (http://hancheol:36004/): Traceback (most recent call last):
  File "/opt/ros/kinetic/lib/python2.7/dist-packages/rospy/impl/tcpros_base.py", line 555, in connect
    self.socket.connect((dest_addr, dest_port))
  File "/usr/lib/python2.7/socket.py", line 228, in meth
    return getattr(self._sock,name)(*args)
error: [Errno 111] Connection refused

[rospy.internal][WARNING] 2017-03-30 15:51:31,909: Unknown error initiating TCP/IP socket to hancheol:38363 (http://hancheol:36004/): Traceback (most recent call last):
  File "/opt/ros/kinetic/lib/python2.7/dist-packages/rospy/impl/tcpros_base.py", line 555, in connect
    self.socket.connect((dest_addr, dest_port))
  File "/usr/lib/python2.7/socket.py", line 228, in meth
    return getattr(self._sock,name)(*args)
error: [Errno 111] Connection refused

[rospy.internal][INFO] 2017-03-30 15:51:31,911: topic[/rrbot/camera1/image_raw/compressed/parameter_descriptions] removing connection to http://hancheol:36004/
[rospy.internal][INFO] 2017-03-30 15:51:31,912: topic[/rrbot/camera1/image_raw/compressedDepth/parameter_updates] removing connection to http://hancheol:36004/
[rospy.internal][WARNING] 2017-03-30 15:51:31,913: Unknown error initiating TCP/IP socket to hancheol:38363 (http://hancheol:36004/): Traceback (most recent call last):
  File "/opt/ros/kinetic/lib/python2.7/dist-packages/rospy/impl/tcpros_base.py", line 555, in connect
    self.socket.connect((dest_addr, dest_port))
  File "/usr/lib/python2.7/socket.py", line 228, in meth
    return getattr(self._sock,name)(*args)
error: [Errno 111] Connection refused

[rospy.internal][WARNING] 2017-03-30 15:51:31,914: Unknown error initiating TCP/IP socket to hancheol:38363 (http://hancheol:36004/): Traceback (most recent call last):
  File "/opt/ros/kinetic/lib/python2.7/dist-packages/rospy/impl/tcpros_base.py", line 555, in connect
    self.socket.connect((dest_addr, dest_port))
  File "/usr/lib/python2.7/socket.py", line 228, in meth
    return getattr(self._sock,name)(*args)
error: [Errno 111] Connection refused

[rospy.internal][WARNING] 2017-03-30 15:51:31,915: Unknown error initiating TCP/IP socket to hancheol:38363 (http://hancheol:36004/): Traceback (most recent call last):
  File "/opt/ros/kinetic/lib/python2.7/dist-packages/rospy/impl/tcpros_base.py", line 555, in connect
    self.socket.connect((dest_addr, dest_port))
  File "/usr/lib/python2.7/socket.py", line 228, in meth
    return getattr(self._sock,name)(*args)
error: [Errno 111] Connection refused

[rospy.internal][INFO] 2017-03-30 15:51:31,919: topic[/rrbot/camera1/image_raw/theora/parameter_updates] removing connection to http://hancheol:36004/
[rospy.internal][INFO] 2017-03-30 15:51:31,919: topic[/rrbot/camera1/image_raw/theora/parameter_descriptions] removing connection to http://hancheol:36004/
[rospy.internal][INFO] 2017-03-30 15:51:31,918: topic[/rrbot/camera1/image_raw/compressed/parameter_updates] removing connection to http://hancheol:36004/
[rospy.internal][WARNING] 2017-03-30 15:51:32,693: Unknown error initiating TCP/IP socket to hancheol:38363 (http://hancheol:36004/): Traceback (most recent call last):
  File "/opt/ros/kinetic/lib/python2.7/dist-packages/rospy/impl/tcpros_base.py", line 555, in connect
    self.socket.connect((dest_addr, dest_port))
  File "/usr/lib/python2.7/socket.py", line 228, in meth
    return getattr(self._sock,name)(*args)
error: [Errno 111] Connection refused

[rospy.internal][INFO] 2017-03-30 15:51:32,693: topic[/clock] removing connection to http://hancheol:36004/
[rospy.internal][WARNING] 2017-03-30 15:51:32,725: Unknown error initiating TCP/IP socket to hancheol:38363 (http://hancheol:36004/): Traceback (most recent call last):
  File "/opt/ros/kinetic/lib/python2.7/dist-packages/rospy/impl/tcpros_base.py", line 555, in connect
    self.socket.connect((dest_addr, dest_port))
  File "/usr/lib/python2.7/socket.py", line 228, in meth
    return getattr(self._sock,name)(*args)
error: [Errno 111] Connection refused

[rospy.internal][INFO] 2017-03-30 15:51:32,726: topic[/gazebo/parameter_descriptions] removing connection to http://hancheol:36004/
[rospy.internal][WARNING] 2017-03-30 15:51:32,731: Unknown error initiating TCP/IP socket to hancheol:38363 (http://hancheol:36004/): Traceback (most recent call last):
  File "/opt/ros/kinetic/lib/python2.7/dist-packages/rospy/impl/tcpros_base.py", line 555, in connect
    self.socket.connect((dest_addr, dest_port))
  File "/usr/lib/python2.7/socket.py", line 228, in meth
    return getattr(self._sock,name)(*args)
error: [Errno 111] Connection refused

[rospy.internal][INFO] 2017-03-30 15:51:32,732: topic[/gazebo/parameter_updates] removing connection to http://hancheol:36004/
[rospy.internal][WARNING] 2017-03-30 15:51:45,613: Unknown error initiating TCP/IP socket to hancheol:38363 (http://hancheol:36004/): Traceback (most recent call last):
  File "/opt/ros/kinetic/lib/python2.7/dist-packages/rospy/impl/tcpros_base.py", line 555, in connect
    self.socket.connect((dest_addr, dest_port))
  File "/usr/lib/python2.7/socket.py", line 228, in meth
    return getattr(self._sock,name)(*args)
error: [Errno 111] Connection refused

[rospy.internal][INFO] 2017-03-30 15:51:45,614: topic[/rrbot/joint_states] removing connection to http://hancheol:36004/
[rospy.internal][INFO] 2017-03-30 16:04:16,046: topic impl's ref count is zero, deleting topic /rrbot/joint1_position_controller/command...
[rospy.internal][INFO] 2017-03-30 16:04:16,048: topic impl's ref count is zero, deleting topic /rrbot/joint_states...
[rospy.internal][INFO] 2017-03-30 16:04:16,048: topic[/rrbot/joint_states] removing connection to /acrobot_rqt
[rospy.internal][ERROR] 2017-03-30 16:04:16,050: Unable to initiate TCP/IP socket to hancheol:36534 (http://hancheol:45240/): Traceback (most recent call last):
  File "/opt/ros/kinetic/lib/python2.7/dist-packages/rospy/impl/tcpros_base.py", line 557, in connect
    self.read_header()
  File "/opt/ros/kinetic/lib/python2.7/dist-packages/rospy/impl/tcpros_base.py", line 650, in read_header
    self._validate_header(read_ros_handshake_header(sock, self.read_buff, self.protocol.buff_size))
  File "/opt/ros/kinetic/lib/python2.7/dist-packages/rospy/impl/tcpros_base.py", line 593, in _validate_header
    raise TransportInitError("remote error reported: %s"%header['error'])
TransportInitError: remote error reported: [/acrobot_rqt] is not a publisher of [/rrbot/joint_states]. Topics are [['/rosout', 'rosgraph_msgs/Log']]

[rospy.internal][INFO] 2017-03-30 16:04:16,055: topic impl's ref count is zero, deleting topic /rrbot/joint_states...
[rospy.internal][INFO] 2017-03-30 16:04:16,055: topic[/rrbot/joint_states] removing connection to http://hancheol:45240/
[rospy.core][INFO] 2017-03-30 16:04:16,163: signal_shutdown [atexit]
[rospy.impl.masterslave][INFO] 2017-03-30 16:04:16,196: atexit
